<?xml version='1.0' encoding='utf-8'?>
<robot name="force_control_gripper">
    <link name="left_figure">
        <inertial>
            <origin xyz="0.0039140878713019465 0.0363213180478208 -0.019212149166772524" rpy="0.0 -0.0 0.0" />
            <mass value="0.7290858212317849" />
            <inertia ixx="0.0009567320931237102" iyy="0.00018598568132813936" izz="0.0009503563127682703" ixy="-4.319953187031681e-05" iyz="-6.712899236421582e-05" ixz="-1.8346003333227254e-07" />
        </inertial>
        <visual name="left_figure_visual">
            <origin xyz="0.0054782322593601405 -0.002538307703411997 0.054754926046441506" rpy="-3.141592653589793 3.570089879990766e-13 -3.141592653589793" />
            <geometry>
                <mesh filename="meshes/left_figure.stl" scale="0.001 0.001 0.001" />
            </geometry>
        </visual>
        <collision name="left_figure_collision">
            <origin xyz="0.0054782322593601405 -0.002538307703411997 0.054754926046441506" rpy="-3.141592653589793 3.570089879990766e-13 -3.141592653589793" />
            <geometry>
                <mesh filename="meshes/left_figure.stl" scale="0.001 0.001 0.001" />
            </geometry>
        </collision>
    </link>
    <link name="right_figure">
        <inertial>
            <origin xyz="0.007085909275558089 -0.036321318047820905 0.030787850065817714" rpy="0.0 -0.0 0.0" />
            <mass value="0.729085821231785" />
            <inertia ixx="0.0009567320931237119" iyy="0.0001859856813281411" izz="0.0009503563127682708" ixy="-4.319953187031697e-05" iyz="6.712899236421604e-05" ixz="1.834600333322099e-07" />
        </inertial>
        <visual name="right_figure_visual">
            <origin xyz="0.005521764887499895 0.002538307703411878 0.10475492527903174" rpy="-3.141592653589793 3.5688652331916185e-13 0.0" />
            <geometry>
                <mesh filename="meshes/right_figure.stl" scale="0.001 0.001 0.001" />
            </geometry>
        </visual>
        <collision name="right_figure_collision">
            <origin xyz="0.005521764887499895 0.002538307703411878 0.10475492527903174" rpy="-3.141592653589793 3.5688652331916185e-13 0.0" />
            <geometry>
                <mesh filename="meshes/right_figure.stl" scale="0.001 0.001 0.001" />
            </geometry>
        </collision>
    </link>
    <link name="base-1">
        <inertial>
            <origin xyz="6.886875168914372e-06 -0.03027526112285501 0.00011938041814217152" rpy="0.0 0.0 0.0" />
            <mass value="2.860956390976862" />
            <inertia ixx="0.015979939915842623" iyy="0.015695110232053375" izz="0.001461791518230924" ixy="-1.2192499532982057e-06" iyz="-2.9345391647553618e-06" ixz="0.0008557882295470238" />
        </inertial>
        <visual name="base-1_visual">
            <origin xyz="0.0 0.0 0.0" rpy="0.0 0.0 0.0" />
            <geometry>
                <mesh filename="meshes/base-1.stl" scale="0.001 0.001 0.001" />
            </geometry>
        </visual>
        <collision name="base-1_collision">
            <origin xyz="0.0 0.0 0.0" rpy="0.0 0.0 0.0" />
            <geometry>
                <mesh filename="meshes/base-1.stl" scale="0.001 0.001 0.001" />
            </geometry>
        </collision>
    </link>
    <joint name="base-1_Slider-15" type="prismatic">
        <origin xyz="-0.00548381 0.0025 -0.05" rpy="0.0 -0.0 0.0" />
        <parent link="base-1" />
        <child link="left_figure" />
        <axis xyz="0.0 0.0 1.0" />
        <limit lower="0.0" upper="0.0992" effort="1000000" velocity="1000000" />
    </joint>
    <joint name="base-1_Slider-16" type="prismatic">
        <origin xyz="-0.00548381 0.0025 0.1" rpy="3.141592653589793 -0.0 0.0" />
        <parent link="base-1" />
        <child link="right_figure" />
        <axis xyz="0.0 0.0 1.0" />
        <limit lower="0.0" upper="0.0992" effort="1000000" velocity="1000000" />
    </joint>
</robot>